Workbook

Sheet Instructions
A1: MS Excel Practical Exam
A2: Total Questions: 30
A3: Difficulty Level: Medium
A4: Syllabus: Formulas, Logical Functions, Lookups, INDEX-MATCH, Pivot Tables & Charts, Data Analysis
A5: Attempt all questions using appropriate Excel tools/functions.

Sheet Sales_Data
A1: Order_ID | B1: Region | C1: Salesperson | D1: Product | E1: Quantity | F1: Unit_Price | G1: Sales_Date
A2: 301 | B2: North | C2: Amit | D2: Laptop | E2: 2 | F2: 45000 | G2: 05-01-2025
A3: 302 | B3: South | C3: Riya | D3: Mobile | E3: 5 | F3: 15000 | G3: 07-01-2025
A4: 303 | B4: East | C4: Kunal | D4: Tablet | E4: 3 | F4: 18000 | G4: 10-01-2025
A5: 304 | B5: West | C5: Neha | D5: Laptop | E5: 1 | F5: 45000 | G5: 12-01-2025
A6: 305 | B6: North | C6: Amit | D6: Mobile | E6: 4 | F6: 15000 | G6: 15-01-2025
A7: 306 | B7: South | C7: Riya | D7: Laptop | E7: 2 | F7: 45000 | G7: 18-01-2025

Sheet Product_Master
A1: Product | B1: Category | C1: GST_%
A2: Laptop | B2: Electronics | C2: 18
A3: Mobile | B3: Electronics | C3: 12
A4: Tablet | B4: Electronics | C4: 12

Sheet Student_Marks
A1: Student_ID | B1: Name | C1: Maths | D1: Statistics | E1: Excel | F1: Attendance_%
A2: 1 | B2: Rahul | C2: 78 | D2: 82 | E2: 85 | F2: 92
A3: 2 | B3: Sneha | C3: 88 | D3: 91 | E3: 90 | F3: 96
A4: 3 | B4: Arjun | C4: 65 | D4: 70 | E4: 72 | F4: 85
A5: 4 | B5: Pooja | C5: 92 | D5: 89 | E5: 94 | F5: 98
A6: 5 | B6: Vikas | C6: 55 | D6: 60 | E6: 58 | F6: 80

Sheet Questions
A1: 1. Calculate Total Sales for each order (Quantity × Unit_Price). | J1: 2
A2: 2. Calculate GST Amount using VLOOKUP from Product_Master. | J2: 2
A3: 3. Find Final Amount payable (Total Sales + GST). | J3: 2
A4: 4. Find Grand Total of Final Amount. | J4: 2
A5: 5. Count total number of orders using COUNTA. | J5: 2
A6: 6. Find Region-wise total sales using SUMIF. | J6: 2
A7: 7. Use IF to classify Quantity as High (>3) or Low (<=3). | J7: 2
A8: 8. Find the maximum and minimum Final Amount. | J8: 2
A9: 9. Extract month name from Sales_Date. | J9: 2
A10: 10. Sort Sales_Data by Final Amount (Descending). | J10: 2
A11: 11. Use INDEX-MATCH to fetch Product Category. | J11: 2
A12: 12. Calculate average marks of each student. | J12: 2
... A30: 30. Protect the Student_Marks sheet. | J30: 2
J32: =SUM(J1:J30) -> 60

Sheet Answers
A1: Order_ID | B1: Region | C1: Salesperson | D1: Product | E1: Quantity | F1: Unit_Price | G1: Sales_Date | I1: Product | J1: Category | K1: GST_% | M1: Student_ID | N1: Name | O1: Maths | P1: Statistics | Q1: Excel | R1: Attendance_%
A2: 301 | B2: North | C2: Amit | D2: Laptop | E2: 2 | F2: 45000 | G2: 05-01-2025 | I2: Laptop | J2: Electronics | K2: 18 | M2: 1 | N2: Rahul | O2: 78 | P2: 82 | Q2: 85 | R2: 92
A3: 302 | B3: South | C3: Riya | D3: Mobile | E3: 5 | F3: 15000 | G3: 07-01-2025 | I3: Mobile | J3: Electronics | K3: 12 | M3: 2 | N3: Sneha | O3: 88 | P3: 91 | Q3: 90 | R3: 96
A4: 303 | B4: East | C4: Kunal | D4: Tablet | E4: 3 | F4: 18000 | G4: 10-01-2025 | I4: Tablet | J4: Electronics | K4: 12 | M4: 3 | N4: Arjun | O4: 65 | P4: 70 | Q4: 72 | R4: 85
A5: 304 | B5: West | C5: Neha | D5: Laptop | E5: 1 | F5: 45000 | G5: 12-01-2025 | M5: 4 | N5: Pooja | O5: 92 | P5: 89 | Q5: 94 | R5: 98
A6: 305 | B6: North | C6: Amit | D6: Mobile | E6: 4 | F6: 15000 | G6: 15-01-2025 | M6: 5 | N6: Vikas | O6: 55 | P6: 60 | Q6: 58 | R6: 80
A7: 306 | B7: South | C7: Riya | D7: Laptop | E7: 2 | F7: 45000 | G7: 18-01-2025
A10: ANSWERS | B10: Q1 | C10: Total Amount
C11: =F2*E2 -> 90000
C12: =F3*E3 -> 75000
C13: =F4*E4 -> 54000
C14: =F5*E5 -> 45000
C15: =F6*E6 -> 60000
C16: =F7*E7 -> 90000
B19: Q2 | C19: GST Amount
C20: =C11*VLOOKUP(D2,$I$1:$K$4,3,0)% -> 16200
C21: =C12*VLOOKUP(D3,$I$1:$K$4,3,0)% -> 9000
C22: =C13*VLOOKUP(D4,$I$1:$K$4,3,0)% -> 6480
C23: =C14*VLOOKUP(D5,$I$1:$K$4,3,0)% -> 8100
C24: =C15*VLOOKUP(D6,$I$1:$K$4,3,0)% -> 7200
C25: =C16*VLOOKUP(D7,$I$1:$K$4,3,0)% -> 16200
B28: Q3 | C28: Final Amount
C29: 106200
C30: 84000
C31: 60480
C32: 53100
C33: 67200
C34: 106200
B37: Q4 | C37: Grand Total of Final Amount
C38: =SUM(C29:C34) -> 477180
B41: Q5 | C41: Count Total Order
C42: =COUNT(E2:E7) -> 6
B45: Q6 | C45: Region | D45: Sales
C46: North | D46: =SUMIF(B2:B7,B2,C11:C16) -> 150000
C47: South | D47: =SUMIF(B3:B8,B3,B14:B18) -> 0
C48: East | D48: =SUMIF(B4:B9,B4,B15:B18) -> 0
C49: West | D49: =SUMIF(B5:B9,B5,B16:B18) -> 0
B52: Q7 | C52: Quantity
C53: =IF(E2>3,"High","Low") -> Low
C54: =IF(E3>3,"High","Low") -> High
...
